[2025-04-21T15:42:47.862+0000] {local_task_job_runner.py:123} INFO - ::group::Pre task execution logs
[2025-04-21T15:42:47.873+0000] {taskinstance.py:2612} INFO - Dependencies all met for dep_context=non-requeueable deps ti=<TaskInstance: stock_data_etl_dbt.dbt_run_transformations manual__2025-04-21T09:27:23.045534+00:00 [queued]>
[2025-04-21T15:42:47.878+0000] {taskinstance.py:2612} INFO - Dependencies all met for dep_context=requeueable deps ti=<TaskInstance: stock_data_etl_dbt.dbt_run_transformations manual__2025-04-21T09:27:23.045534+00:00 [queued]>
[2025-04-21T15:42:47.878+0000] {taskinstance.py:2865} INFO - Starting attempt 2 of 2
[2025-04-21T15:42:47.887+0000] {taskinstance.py:2888} INFO - Executing <Task(BashOperator): dbt_run_transformations> on 2025-04-21 09:27:23.045534+00:00
[2025-04-21T15:42:47.896+0000] {logging_mixin.py:190} WARNING - /home/***/.local/lib/python3.12/site-packages/***/task/task_runner/standard_task_runner.py:70 DeprecationWarning: This process (pid=19306) is multi-threaded, use of fork() may lead to deadlocks in the child.
[2025-04-21T15:42:47.897+0000] {standard_task_runner.py:72} INFO - Started process 19345 to run task
[2025-04-21T15:42:47.896+0000] {standard_task_runner.py:104} INFO - Running: ['***', 'tasks', 'run', 'stock_data_etl_dbt', 'dbt_run_transformations', 'manual__2025-04-21T09:27:23.045534+00:00', '--job-id', '45', '--raw', '--subdir', 'DAGS_FOLDER/Stock_built_ELT.py', '--cfg-path', '/tmp/tmpgdh9bg7z']
[2025-04-21T15:42:47.898+0000] {standard_task_runner.py:105} INFO - Job 45: Subtask dbt_run_transformations
[2025-04-21T15:42:47.931+0000] {task_command.py:467} INFO - Running <TaskInstance: stock_data_etl_dbt.dbt_run_transformations manual__2025-04-21T09:27:23.045534+00:00 [running]> on host 712e28762a67
[2025-04-21T15:42:47.981+0000] {taskinstance.py:3131} INFO - Exporting env vars: AIRFLOW_CTX_DAG_OWNER='***' AIRFLOW_CTX_DAG_ID='stock_data_etl_dbt' AIRFLOW_CTX_TASK_ID='dbt_run_transformations' AIRFLOW_CTX_EXECUTION_DATE='2025-04-21T09:27:23.045534+00:00' AIRFLOW_CTX_TRY_NUMBER='2' AIRFLOW_CTX_DAG_RUN_ID='manual__2025-04-21T09:27:23.045534+00:00'
[2025-04-21T15:42:47.982+0000] {taskinstance.py:731} INFO - ::endgroup::
[2025-04-21T15:42:47.984+0000] {subprocess.py:63} INFO - Tmp dir root location: /tmp
[2025-04-21T15:42:47.985+0000] {subprocess.py:75} INFO - Running command: ['/usr/bin/bash', '-c', '/home/***/.local/bin/dbt run --select models/intermediate/moving_averages models/intermediate/rsi --profiles-dir /opt/***/dbt --project-dir /opt/***/dbt']
[2025-04-21T15:42:47.992+0000] {subprocess.py:86} INFO - Output:
[2025-04-21T15:42:50.944+0000] {subprocess.py:93} INFO - [0m15:42:50  Running with dbt=1.7.19
[2025-04-21T15:42:51.914+0000] {subprocess.py:93} INFO - [0m15:42:51  Registered adapter: snowflake=1.7.1
[2025-04-21T15:42:51.935+0000] {subprocess.py:93} INFO - [0m15:42:51  Unable to do partial parsing because profile has changed
[2025-04-21T15:42:52.757+0000] {subprocess.py:93} INFO - [0m15:42:52  Encountered an error:
[2025-04-21T15:42:52.758+0000] {subprocess.py:93} INFO - Compilation Error
[2025-04-21T15:42:52.758+0000] {subprocess.py:93} INFO -   Model 'model.my_new_project.RSI' (models/dbt_transformation/RSI.sql) depends on a source named 'raw.stock_data' which was not found
[2025-04-21T15:42:53.625+0000] {subprocess.py:97} INFO - Command exited with return code 2
[2025-04-21T15:42:53.662+0000] {taskinstance.py:3310} ERROR - Task failed with exception
Traceback (most recent call last):
  File "/home/airflow/.local/lib/python3.12/site-packages/airflow/models/taskinstance.py", line 767, in _execute_task
    result = _execute_callable(context=context, **execute_callable_kwargs)
             ^^^^^^^^^^^^^^^^^^^^^^^^^^^^^^^^^^^^^^^^^^^^^^^^^^^^^^^^^^^^^
  File "/home/airflow/.local/lib/python3.12/site-packages/airflow/models/taskinstance.py", line 733, in _execute_callable
    return ExecutionCallableRunner(
           ^^^^^^^^^^^^^^^^^^^^^^^^
  File "/home/airflow/.local/lib/python3.12/site-packages/airflow/utils/operator_helpers.py", line 252, in run
    return self.func(*args, **kwargs)
           ^^^^^^^^^^^^^^^^^^^^^^^^^^
  File "/home/airflow/.local/lib/python3.12/site-packages/airflow/models/baseoperator.py", line 406, in wrapper
    return func(self, *args, **kwargs)
           ^^^^^^^^^^^^^^^^^^^^^^^^^^^
  File "/home/airflow/.local/lib/python3.12/site-packages/airflow/operators/bash.py", line 249, in execute
    raise AirflowException(
airflow.exceptions.AirflowException: Bash command failed. The command returned a non-zero exit code 2.
[2025-04-21T15:42:53.670+0000] {taskinstance.py:1225} INFO - Marking task as FAILED. dag_id=stock_data_etl_dbt, task_id=dbt_run_transformations, run_id=manual__2025-04-21T09:27:23.045534+00:00, execution_date=20250421T092723, start_date=20250421T154247, end_date=20250421T154253
[2025-04-21T15:42:53.691+0000] {taskinstance.py:340} INFO - ::group::Post task execution logs
[2025-04-21T15:42:53.692+0000] {standard_task_runner.py:124} ERROR - Failed to execute job 45 for task dbt_run_transformations (Bash command failed. The command returned a non-zero exit code 2.; 19345)
Traceback (most recent call last):
  File "/home/airflow/.local/lib/python3.12/site-packages/airflow/task/task_runner/standard_task_runner.py", line 117, in _start_by_fork
    ret = args.func(args, dag=self.dag)
          ^^^^^^^^^^^^^^^^^^^^^^^^^^^^^
  File "/home/airflow/.local/lib/python3.12/site-packages/airflow/cli/cli_config.py", line 49, in command
    return func(*args, **kwargs)
           ^^^^^^^^^^^^^^^^^^^^^
  File "/home/airflow/.local/lib/python3.12/site-packages/airflow/utils/cli.py", line 115, in wrapper
    return f(*args, **kwargs)
           ^^^^^^^^^^^^^^^^^^
  File "/home/airflow/.local/lib/python3.12/site-packages/airflow/cli/commands/task_command.py", line 483, in task_run
    task_return_code = _run_task_by_selected_method(args, _dag, ti)
                       ^^^^^^^^^^^^^^^^^^^^^^^^^^^^^^^^^^^^^^^^^^^^
  File "/home/airflow/.local/lib/python3.12/site-packages/airflow/cli/commands/task_command.py", line 256, in _run_task_by_selected_method
    return _run_raw_task(args, ti)
           ^^^^^^^^^^^^^^^^^^^^^^^
  File "/home/airflow/.local/lib/python3.12/site-packages/airflow/cli/commands/task_command.py", line 341, in _run_raw_task
    return ti._run_raw_task(
           ^^^^^^^^^^^^^^^^^
  File "/home/airflow/.local/lib/python3.12/site-packages/airflow/utils/session.py", line 97, in wrapper
    return func(*args, session=session, **kwargs)
           ^^^^^^^^^^^^^^^^^^^^^^^^^^^^^^^^^^^^^^
  File "/home/airflow/.local/lib/python3.12/site-packages/airflow/models/taskinstance.py", line 3004, in _run_raw_task
    return _run_raw_task(
           ^^^^^^^^^^^^^^
  File "/home/airflow/.local/lib/python3.12/site-packages/airflow/models/taskinstance.py", line 273, in _run_raw_task
    TaskInstance._execute_task_with_callbacks(
  File "/home/airflow/.local/lib/python3.12/site-packages/airflow/models/taskinstance.py", line 3158, in _execute_task_with_callbacks
    result = self._execute_task(context, task_orig)
             ^^^^^^^^^^^^^^^^^^^^^^^^^^^^^^^^^^^^^^
  File "/home/airflow/.local/lib/python3.12/site-packages/airflow/models/taskinstance.py", line 3182, in _execute_task
    return _execute_task(self, context, task_orig)
           ^^^^^^^^^^^^^^^^^^^^^^^^^^^^^^^^^^^^^^^
  File "/home/airflow/.local/lib/python3.12/site-packages/airflow/models/taskinstance.py", line 767, in _execute_task
    result = _execute_callable(context=context, **execute_callable_kwargs)
             ^^^^^^^^^^^^^^^^^^^^^^^^^^^^^^^^^^^^^^^^^^^^^^^^^^^^^^^^^^^^^
  File "/home/airflow/.local/lib/python3.12/site-packages/airflow/models/taskinstance.py", line 733, in _execute_callable
    return ExecutionCallableRunner(
           ^^^^^^^^^^^^^^^^^^^^^^^^
  File "/home/airflow/.local/lib/python3.12/site-packages/airflow/utils/operator_helpers.py", line 252, in run
    return self.func(*args, **kwargs)
           ^^^^^^^^^^^^^^^^^^^^^^^^^^
  File "/home/airflow/.local/lib/python3.12/site-packages/airflow/models/baseoperator.py", line 406, in wrapper
    return func(self, *args, **kwargs)
           ^^^^^^^^^^^^^^^^^^^^^^^^^^^
  File "/home/airflow/.local/lib/python3.12/site-packages/airflow/operators/bash.py", line 249, in execute
    raise AirflowException(
airflow.exceptions.AirflowException: Bash command failed. The command returned a non-zero exit code 2.
[2025-04-21T15:42:53.725+0000] {local_task_job_runner.py:266} INFO - Task exited with return code 1
[2025-04-21T15:42:53.750+0000] {taskinstance.py:3900} INFO - 0 downstream tasks scheduled from follow-on schedule check
[2025-04-21T15:42:53.753+0000] {local_task_job_runner.py:245} INFO - ::endgroup::
