[2025-04-20T05:09:54.461+0000] {local_task_job_runner.py:123} INFO - ::group::Pre task execution logs
[2025-04-20T05:09:54.480+0000] {taskinstance.py:2612} INFO - Dependencies all met for dep_context=non-requeueable deps ti=<TaskInstance: BuildELT_dbt.dbt_run manual__2025-04-20T05:09:53.413941+00:00 [queued]>
[2025-04-20T05:09:54.487+0000] {taskinstance.py:2612} INFO - Dependencies all met for dep_context=requeueable deps ti=<TaskInstance: BuildELT_dbt.dbt_run manual__2025-04-20T05:09:53.413941+00:00 [queued]>
[2025-04-20T05:09:54.488+0000] {taskinstance.py:2865} INFO - Starting attempt 1 of 1
[2025-04-20T05:09:54.498+0000] {taskinstance.py:2888} INFO - Executing <Task(BashOperator): dbt_run> on 2025-04-20 05:09:53.413941+00:00
[2025-04-20T05:09:54.506+0000] {standard_task_runner.py:104} INFO - Running: ['***', 'tasks', 'run', 'BuildELT_dbt', 'dbt_run', 'manual__2025-04-20T05:09:53.413941+00:00', '--job-id', '4', '--raw', '--subdir', 'DAGS_FOLDER/build_elt_with_dbt.py', '--cfg-path', '/tmp/tmp2ec5ltvj']
[2025-04-20T05:09:54.509+0000] {standard_task_runner.py:105} INFO - Job 4: Subtask dbt_run
[2025-04-20T05:09:54.509+0000] {logging_mixin.py:190} WARNING - /home/***/.local/lib/python3.12/site-packages/***/task/task_runner/standard_task_runner.py:70 DeprecationWarning: This process (pid=585) is multi-threaded, use of fork() may lead to deadlocks in the child.
[2025-04-20T05:09:54.509+0000] {standard_task_runner.py:72} INFO - Started process 586 to run task
[2025-04-20T05:09:54.552+0000] {task_command.py:467} INFO - Running <TaskInstance: BuildELT_dbt.dbt_run manual__2025-04-20T05:09:53.413941+00:00 [running]> on host e43c35e614f2
[2025-04-20T05:09:54.618+0000] {taskinstance.py:3131} INFO - Exporting env vars: AIRFLOW_CTX_DAG_OWNER='***' AIRFLOW_CTX_DAG_ID='BuildELT_dbt' AIRFLOW_CTX_TASK_ID='dbt_run' AIRFLOW_CTX_EXECUTION_DATE='2025-04-20T05:09:53.413941+00:00' AIRFLOW_CTX_TRY_NUMBER='1' AIRFLOW_CTX_DAG_RUN_ID='manual__2025-04-20T05:09:53.413941+00:00'
[2025-04-20T05:09:54.619+0000] {taskinstance.py:731} INFO - ::endgroup::
[2025-04-20T05:09:54.635+0000] {subprocess.py:63} INFO - Tmp dir root location: /tmp
[2025-04-20T05:09:54.636+0000] {subprocess.py:75} INFO - Running command: ['/usr/bin/bash', '-c', '/home/***/.local/bin/dbt run --profiles-dir /Users/savithavijayarangan/***/dbt --project-dir /Users/savithavijayarangan/***/dbt']
[2025-04-20T05:09:54.644+0000] {subprocess.py:86} INFO - Output:
[2025-04-20T05:09:54.649+0000] {subprocess.py:93} INFO - /usr/bin/bash: line 1: /home/***/.local/bin/dbt: No such file or directory
[2025-04-20T05:09:54.650+0000] {subprocess.py:97} INFO - Command exited with return code 127
[2025-04-20T05:09:54.661+0000] {taskinstance.py:3310} ERROR - Task failed with exception
Traceback (most recent call last):
  File "/home/airflow/.local/lib/python3.12/site-packages/airflow/models/taskinstance.py", line 767, in _execute_task
    result = _execute_callable(context=context, **execute_callable_kwargs)
             ^^^^^^^^^^^^^^^^^^^^^^^^^^^^^^^^^^^^^^^^^^^^^^^^^^^^^^^^^^^^^
  File "/home/airflow/.local/lib/python3.12/site-packages/airflow/models/taskinstance.py", line 733, in _execute_callable
    return ExecutionCallableRunner(
           ^^^^^^^^^^^^^^^^^^^^^^^^
  File "/home/airflow/.local/lib/python3.12/site-packages/airflow/utils/operator_helpers.py", line 252, in run
    return self.func(*args, **kwargs)
           ^^^^^^^^^^^^^^^^^^^^^^^^^^
  File "/home/airflow/.local/lib/python3.12/site-packages/airflow/models/baseoperator.py", line 406, in wrapper
    return func(self, *args, **kwargs)
           ^^^^^^^^^^^^^^^^^^^^^^^^^^^
  File "/home/airflow/.local/lib/python3.12/site-packages/airflow/operators/bash.py", line 249, in execute
    raise AirflowException(
airflow.exceptions.AirflowException: Bash command failed. The command returned a non-zero exit code 127.
[2025-04-20T05:09:54.667+0000] {taskinstance.py:1225} INFO - Marking task as FAILED. dag_id=BuildELT_dbt, task_id=dbt_run, run_id=manual__2025-04-20T05:09:53.413941+00:00, execution_date=20250420T050953, start_date=20250420T050954, end_date=20250420T050954
[2025-04-20T05:09:54.678+0000] {taskinstance.py:340} INFO - ::group::Post task execution logs
[2025-04-20T05:09:54.678+0000] {standard_task_runner.py:124} ERROR - Failed to execute job 4 for task dbt_run (Bash command failed. The command returned a non-zero exit code 127.; 586)
Traceback (most recent call last):
  File "/home/airflow/.local/lib/python3.12/site-packages/airflow/task/task_runner/standard_task_runner.py", line 117, in _start_by_fork
    ret = args.func(args, dag=self.dag)
          ^^^^^^^^^^^^^^^^^^^^^^^^^^^^^
  File "/home/airflow/.local/lib/python3.12/site-packages/airflow/cli/cli_config.py", line 49, in command
    return func(*args, **kwargs)
           ^^^^^^^^^^^^^^^^^^^^^
  File "/home/airflow/.local/lib/python3.12/site-packages/airflow/utils/cli.py", line 115, in wrapper
    return f(*args, **kwargs)
           ^^^^^^^^^^^^^^^^^^
  File "/home/airflow/.local/lib/python3.12/site-packages/airflow/cli/commands/task_command.py", line 483, in task_run
    task_return_code = _run_task_by_selected_method(args, _dag, ti)
                       ^^^^^^^^^^^^^^^^^^^^^^^^^^^^^^^^^^^^^^^^^^^^
  File "/home/airflow/.local/lib/python3.12/site-packages/airflow/cli/commands/task_command.py", line 256, in _run_task_by_selected_method
    return _run_raw_task(args, ti)
           ^^^^^^^^^^^^^^^^^^^^^^^
  File "/home/airflow/.local/lib/python3.12/site-packages/airflow/cli/commands/task_command.py", line 341, in _run_raw_task
    return ti._run_raw_task(
           ^^^^^^^^^^^^^^^^^
  File "/home/airflow/.local/lib/python3.12/site-packages/airflow/utils/session.py", line 97, in wrapper
    return func(*args, session=session, **kwargs)
           ^^^^^^^^^^^^^^^^^^^^^^^^^^^^^^^^^^^^^^
  File "/home/airflow/.local/lib/python3.12/site-packages/airflow/models/taskinstance.py", line 3004, in _run_raw_task
    return _run_raw_task(
           ^^^^^^^^^^^^^^
  File "/home/airflow/.local/lib/python3.12/site-packages/airflow/models/taskinstance.py", line 273, in _run_raw_task
    TaskInstance._execute_task_with_callbacks(
  File "/home/airflow/.local/lib/python3.12/site-packages/airflow/models/taskinstance.py", line 3158, in _execute_task_with_callbacks
    result = self._execute_task(context, task_orig)
             ^^^^^^^^^^^^^^^^^^^^^^^^^^^^^^^^^^^^^^
  File "/home/airflow/.local/lib/python3.12/site-packages/airflow/models/taskinstance.py", line 3182, in _execute_task
    return _execute_task(self, context, task_orig)
           ^^^^^^^^^^^^^^^^^^^^^^^^^^^^^^^^^^^^^^^
  File "/home/airflow/.local/lib/python3.12/site-packages/airflow/models/taskinstance.py", line 767, in _execute_task
    result = _execute_callable(context=context, **execute_callable_kwargs)
             ^^^^^^^^^^^^^^^^^^^^^^^^^^^^^^^^^^^^^^^^^^^^^^^^^^^^^^^^^^^^^
  File "/home/airflow/.local/lib/python3.12/site-packages/airflow/models/taskinstance.py", line 733, in _execute_callable
    return ExecutionCallableRunner(
           ^^^^^^^^^^^^^^^^^^^^^^^^
  File "/home/airflow/.local/lib/python3.12/site-packages/airflow/utils/operator_helpers.py", line 252, in run
    return self.func(*args, **kwargs)
           ^^^^^^^^^^^^^^^^^^^^^^^^^^
  File "/home/airflow/.local/lib/python3.12/site-packages/airflow/models/baseoperator.py", line 406, in wrapper
    return func(self, *args, **kwargs)
           ^^^^^^^^^^^^^^^^^^^^^^^^^^^
  File "/home/airflow/.local/lib/python3.12/site-packages/airflow/operators/bash.py", line 249, in execute
    raise AirflowException(
airflow.exceptions.AirflowException: Bash command failed. The command returned a non-zero exit code 127.
[2025-04-20T05:09:54.696+0000] {local_task_job_runner.py:266} INFO - Task exited with return code 1
[2025-04-20T05:09:54.712+0000] {taskinstance.py:3900} INFO - 0 downstream tasks scheduled from follow-on schedule check
[2025-04-20T05:09:54.715+0000] {local_task_job_runner.py:245} INFO - ::endgroup::
